2022-03-19 22:32:17,622 ERROR: Exception on /reset_password_request [GET] [in C:\microblog\venv\lib\site-packages\flask\app.py:1457]
Traceback (most recent call last):
  File "C:\microblog\venv\lib\site-packages\flask\app.py", line 2073, in wsgi_app
    response = self.full_dispatch_request()
  File "C:\microblog\venv\lib\site-packages\flask\app.py", line 1518, in full_dispatch_request
    rv = self.handle_user_exception(e)
  File "C:\microblog\venv\lib\site-packages\flask\app.py", line 1516, in full_dispatch_request
    rv = self.dispatch_request()
  File "C:\microblog\venv\lib\site-packages\flask\app.py", line 1502, in dispatch_request
    return self.ensure_sync(self.view_functions[rule.endpoint])(**req.view_args)
  File "C:\microblog\app\routes.py", line 182, in reset_password_request
    return render_template('reset_password_request.html',
  File "C:\microblog\venv\lib\site-packages\flask\templating.py", line 148, in render_template
    ctx.app.jinja_env.get_or_select_template(template_name_or_list),
  File "C:\microblog\venv\lib\site-packages\jinja2\environment.py", line 1068, in get_or_select_template
    return self.get_template(template_name_or_list, parent, globals)
  File "C:\microblog\venv\lib\site-packages\jinja2\environment.py", line 997, in get_template
    return self._load_template(name, globals)
  File "C:\microblog\venv\lib\site-packages\jinja2\environment.py", line 958, in _load_template
    template = self.loader.load(self, name, self.make_globals(globals))
  File "C:\microblog\venv\lib\site-packages\jinja2\loaders.py", line 125, in load
    source, filename, uptodate = self.get_source(environment, name)
  File "C:\microblog\venv\lib\site-packages\flask\templating.py", line 59, in get_source
    return self._get_source_fast(environment, template)
  File "C:\microblog\venv\lib\site-packages\flask\templating.py", line 95, in _get_source_fast
    raise TemplateNotFound(template)
jinja2.exceptions.TemplateNotFound: reset_password_request.html
2022-03-19 22:33:44,258 INFO: Microblog startup [in C:\microblog\app\__init__.py:42]
2022-03-19 22:33:56,825 ERROR: Exception on /reset_password_request [POST] [in C:\microblog\venv\lib\site-packages\flask\app.py:1457]
Traceback (most recent call last):
  File "C:\microblog\venv\lib\site-packages\flask\app.py", line 2073, in wsgi_app
    response = self.full_dispatch_request()
  File "C:\microblog\venv\lib\site-packages\flask\app.py", line 1518, in full_dispatch_request
    rv = self.handle_user_exception(e)
  File "C:\microblog\venv\lib\site-packages\flask\app.py", line 1516, in full_dispatch_request
    rv = self.dispatch_request()
  File "C:\microblog\venv\lib\site-packages\flask\app.py", line 1502, in dispatch_request
    return self.ensure_sync(self.view_functions[rule.endpoint])(**req.view_args)
  File "C:\microblog\app\routes.py", line 179, in reset_password_request
    send_password_reset_email(user)
  File "C:\microblog\app\email.py", line 14, in send_password_reset_email
    send_email('[Microblog] Reset Your Password',
  File "C:\microblog\app\email.py", line 10, in send_email
    mail.send(msg)
  File "C:\microblog\venv\lib\site-packages\flask_mail.py", line 491, in send
    with self.connect() as connection:
  File "C:\microblog\venv\lib\site-packages\flask_mail.py", line 144, in __enter__
    self.host = self.configure_host()
  File "C:\microblog\venv\lib\site-packages\flask_mail.py", line 158, in configure_host
    host = smtplib.SMTP(self.mail.server, self.mail.port)
  File "C:\Users\guwor\AppData\Local\Programs\Python\Python310\lib\smtplib.py", line 255, in __init__
    (code, msg) = self.connect(host, port)
  File "C:\Users\guwor\AppData\Local\Programs\Python\Python310\lib\smtplib.py", line 341, in connect
    self.sock = self._get_socket(host, port, self.timeout)
  File "C:\Users\guwor\AppData\Local\Programs\Python\Python310\lib\smtplib.py", line 312, in _get_socket
    return socket.create_connection((host, port), timeout,
  File "C:\Users\guwor\AppData\Local\Programs\Python\Python310\lib\socket.py", line 845, in create_connection
    raise err
  File "C:\Users\guwor\AppData\Local\Programs\Python\Python310\lib\socket.py", line 833, in create_connection
    sock.connect(sa)
ConnectionRefusedError: [WinError 10061] No connection could be made because the target machine actively refused it
2022-03-19 22:36:30,150 INFO: Microblog startup [in C:\microblog\app\__init__.py:42]
2022-03-19 22:36:46,217 ERROR: Exception on /reset_password_request [POST] [in C:\microblog\venv\lib\site-packages\flask\app.py:1457]
Traceback (most recent call last):
  File "C:\microblog\venv\lib\site-packages\flask\app.py", line 2073, in wsgi_app
    response = self.full_dispatch_request()
  File "C:\microblog\venv\lib\site-packages\flask\app.py", line 1518, in full_dispatch_request
    rv = self.handle_user_exception(e)
  File "C:\microblog\venv\lib\site-packages\flask\app.py", line 1516, in full_dispatch_request
    rv = self.dispatch_request()
  File "C:\microblog\venv\lib\site-packages\flask\app.py", line 1502, in dispatch_request
    return self.ensure_sync(self.view_functions[rule.endpoint])(**req.view_args)
  File "C:\microblog\app\routes.py", line 179, in reset_password_request
    send_password_reset_email(user)
  File "C:\microblog\app\email.py", line 14, in send_password_reset_email
    send_email('[Microblog] Reset Your Password',
  File "C:\microblog\app\email.py", line 10, in send_email
    mail.send(msg)
  File "C:\microblog\venv\lib\site-packages\flask_mail.py", line 491, in send
    with self.connect() as connection:
  File "C:\microblog\venv\lib\site-packages\flask_mail.py", line 144, in __enter__
    self.host = self.configure_host()
  File "C:\microblog\venv\lib\site-packages\flask_mail.py", line 158, in configure_host
    host = smtplib.SMTP(self.mail.server, self.mail.port)
  File "C:\Users\guwor\AppData\Local\Programs\Python\Python310\lib\smtplib.py", line 255, in __init__
    (code, msg) = self.connect(host, port)
  File "C:\Users\guwor\AppData\Local\Programs\Python\Python310\lib\smtplib.py", line 341, in connect
    self.sock = self._get_socket(host, port, self.timeout)
  File "C:\Users\guwor\AppData\Local\Programs\Python\Python310\lib\smtplib.py", line 312, in _get_socket
    return socket.create_connection((host, port), timeout,
  File "C:\Users\guwor\AppData\Local\Programs\Python\Python310\lib\socket.py", line 845, in create_connection
    raise err
  File "C:\Users\guwor\AppData\Local\Programs\Python\Python310\lib\socket.py", line 833, in create_connection
    sock.connect(sa)
ConnectionRefusedError: [WinError 10061] No connection could be made because the target machine actively refused it
2022-03-19 22:38:50,977 ERROR: Exception on /reset_password_request [POST] [in C:\microblog\venv\lib\site-packages\flask\app.py:1457]
Traceback (most recent call last):
  File "C:\microblog\venv\lib\site-packages\flask\app.py", line 2073, in wsgi_app
    response = self.full_dispatch_request()
  File "C:\microblog\venv\lib\site-packages\flask\app.py", line 1518, in full_dispatch_request
    rv = self.handle_user_exception(e)
  File "C:\microblog\venv\lib\site-packages\flask\app.py", line 1516, in full_dispatch_request
    rv = self.dispatch_request()
  File "C:\microblog\venv\lib\site-packages\flask\app.py", line 1502, in dispatch_request
    return self.ensure_sync(self.view_functions[rule.endpoint])(**req.view_args)
  File "C:\microblog\app\routes.py", line 179, in reset_password_request
    send_password_reset_email(user)
  File "C:\microblog\app\email.py", line 14, in send_password_reset_email
    send_email('[Microblog] Reset Your Password',
  File "C:\microblog\app\email.py", line 10, in send_email
    mail.send(msg)
  File "C:\microblog\venv\lib\site-packages\flask_mail.py", line 491, in send
    with self.connect() as connection:
  File "C:\microblog\venv\lib\site-packages\flask_mail.py", line 144, in __enter__
    self.host = self.configure_host()
  File "C:\microblog\venv\lib\site-packages\flask_mail.py", line 158, in configure_host
    host = smtplib.SMTP(self.mail.server, self.mail.port)
  File "C:\Users\guwor\AppData\Local\Programs\Python\Python310\lib\smtplib.py", line 255, in __init__
    (code, msg) = self.connect(host, port)
  File "C:\Users\guwor\AppData\Local\Programs\Python\Python310\lib\smtplib.py", line 341, in connect
    self.sock = self._get_socket(host, port, self.timeout)
  File "C:\Users\guwor\AppData\Local\Programs\Python\Python310\lib\smtplib.py", line 312, in _get_socket
    return socket.create_connection((host, port), timeout,
  File "C:\Users\guwor\AppData\Local\Programs\Python\Python310\lib\socket.py", line 845, in create_connection
    raise err
  File "C:\Users\guwor\AppData\Local\Programs\Python\Python310\lib\socket.py", line 833, in create_connection
    sock.connect(sa)
ConnectionRefusedError: [WinError 10061] No connection could be made because the target machine actively refused it
2022-03-19 22:43:07,214 INFO: Microblog startup [in C:\microblog\app\__init__.py:42]
