2022-03-25 14:24:44,901 INFO: Microblog startup [in C:\microblog\app\__init__.py:74]
2022-03-25 17:10:01,029 INFO: Microblog startup [in C:\microblog\app\__init__.py:77]
2022-03-25 17:20:03,193 INFO: Microblog startup [in C:\microblog\app\__init__.py:77]
2022-03-25 17:21:40,587 INFO: Microblog startup [in C:\microblog\app\__init__.py:77]
2022-03-25 17:35:10,678 INFO: Microblog startup [in C:\microblog\app\__init__.py:77]
2022-03-29 11:30:41,154 INFO: Microblog startup [in C:\microblog\app\__init__.py:82]
2022-03-29 12:08:49,571 INFO: Microblog startup [in C:\microblog\app\__init__.py:82]
2022-03-29 14:52:18,006 INFO: Microblog startup [in C:\microblog\app\__init__.py:82]
2022-03-29 14:52:26,179 ERROR: Exception on / [GET] [in C:\microblog\venv\lib\site-packages\flask\app.py:1457]
Traceback (most recent call last):
  File "C:\microblog\venv\lib\site-packages\sqlalchemy\engine\base.py", line 1802, in _execute_context
    self.dialect.do_execute(
  File "C:\microblog\venv\lib\site-packages\sqlalchemy\engine\default.py", line 732, in do_execute
    cursor.execute(statement, parameters)
sqlite3.OperationalError: no such table: user

The above exception was the direct cause of the following exception:

Traceback (most recent call last):
  File "C:\microblog\venv\lib\site-packages\flask\app.py", line 2073, in wsgi_app
    response = self.full_dispatch_request()
  File "C:\microblog\venv\lib\site-packages\flask\app.py", line 1518, in full_dispatch_request
    rv = self.handle_user_exception(e)
  File "C:\microblog\venv\lib\site-packages\flask\app.py", line 1514, in full_dispatch_request
    rv = self.preprocess_request()
  File "C:\microblog\venv\lib\site-packages\flask\app.py", line 1857, in preprocess_request
    rv = self.ensure_sync(before_func)()
  File "C:\microblog\app\main\routes.py", line 16, in before_request
    if current_user.is_authenticated:
  File "C:\microblog\venv\lib\site-packages\werkzeug\local.py", line 436, in __get__
    obj = instance._get_current_object()
  File "C:\microblog\venv\lib\site-packages\werkzeug\local.py", line 565, in _get_current_object
    return self.__local()  # type: ignore
  File "C:\microblog\venv\lib\site-packages\flask_login\utils.py", line 26, in <lambda>
    current_user = LocalProxy(lambda: _get_user())
  File "C:\microblog\venv\lib\site-packages\flask_login\utils.py", line 346, in _get_user
    current_app.login_manager._load_user()
  File "C:\microblog\venv\lib\site-packages\flask_login\login_manager.py", line 318, in _load_user
    user = self._user_callback(user_id)
  File "C:\microblog\app\models.py", line 126, in load_user
    return User.query.get(int(id))
  File "<string>", line 2, in get
  File "C:\microblog\venv\lib\site-packages\sqlalchemy\util\deprecations.py", line 401, in warned
    return fn(*args, **kwargs)
  File "C:\microblog\venv\lib\site-packages\sqlalchemy\orm\query.py", line 943, in get
    return self._get_impl(ident, loading.load_on_pk_identity)
  File "C:\microblog\venv\lib\site-packages\sqlalchemy\orm\query.py", line 947, in _get_impl
    return self.session._get_impl(
  File "C:\microblog\venv\lib\site-packages\sqlalchemy\orm\session.py", line 2892, in _get_impl
    return db_load_fn(
  File "C:\microblog\venv\lib\site-packages\sqlalchemy\orm\loading.py", line 530, in load_on_pk_identity
    session.execute(
  File "C:\microblog\venv\lib\site-packages\sqlalchemy\orm\session.py", line 1692, in execute
    result = conn._execute_20(statement, params or {}, execution_options)
  File "C:\microblog\venv\lib\site-packages\sqlalchemy\engine\base.py", line 1614, in _execute_20
    return meth(self, args_10style, kwargs_10style, execution_options)
  File "C:\microblog\venv\lib\site-packages\sqlalchemy\sql\elements.py", line 325, in _execute_on_connection
    return connection._execute_clauseelement(
  File "C:\microblog\venv\lib\site-packages\sqlalchemy\engine\base.py", line 1481, in _execute_clauseelement
    ret = self._execute_context(
  File "C:\microblog\venv\lib\site-packages\sqlalchemy\engine\base.py", line 1845, in _execute_context
    self._handle_dbapi_exception(
  File "C:\microblog\venv\lib\site-packages\sqlalchemy\engine\base.py", line 2026, in _handle_dbapi_exception
    util.raise_(
  File "C:\microblog\venv\lib\site-packages\sqlalchemy\util\compat.py", line 207, in raise_
    raise exception
  File "C:\microblog\venv\lib\site-packages\sqlalchemy\engine\base.py", line 1802, in _execute_context
    self.dialect.do_execute(
  File "C:\microblog\venv\lib\site-packages\sqlalchemy\engine\default.py", line 732, in do_execute
    cursor.execute(statement, parameters)
sqlalchemy.exc.OperationalError: (sqlite3.OperationalError) no such table: user
[SQL: SELECT user.id AS user_id, user.username AS user_username, user.email AS user_email, user.password_hash AS user_password_hash, user.about_me AS user_about_me, user.last_seen AS user_last_seen 
FROM user 
WHERE user.id = ?]
[parameters: (8,)]
(Background on this error at: https://sqlalche.me/e/14/e3q8)
2022-03-29 14:52:56,819 ERROR: Exception on / [GET] [in C:\microblog\venv\lib\site-packages\flask\app.py:1457]
Traceback (most recent call last):
  File "C:\microblog\venv\lib\site-packages\sqlalchemy\engine\base.py", line 1802, in _execute_context
    self.dialect.do_execute(
  File "C:\microblog\venv\lib\site-packages\sqlalchemy\engine\default.py", line 732, in do_execute
    cursor.execute(statement, parameters)
sqlite3.OperationalError: no such table: user

The above exception was the direct cause of the following exception:

Traceback (most recent call last):
  File "C:\microblog\venv\lib\site-packages\flask\app.py", line 2073, in wsgi_app
    response = self.full_dispatch_request()
  File "C:\microblog\venv\lib\site-packages\flask\app.py", line 1518, in full_dispatch_request
    rv = self.handle_user_exception(e)
  File "C:\microblog\venv\lib\site-packages\flask\app.py", line 1514, in full_dispatch_request
    rv = self.preprocess_request()
  File "C:\microblog\venv\lib\site-packages\flask\app.py", line 1857, in preprocess_request
    rv = self.ensure_sync(before_func)()
  File "C:\microblog\app\main\routes.py", line 16, in before_request
    if current_user.is_authenticated:
  File "C:\microblog\venv\lib\site-packages\werkzeug\local.py", line 436, in __get__
    obj = instance._get_current_object()
  File "C:\microblog\venv\lib\site-packages\werkzeug\local.py", line 565, in _get_current_object
    return self.__local()  # type: ignore
  File "C:\microblog\venv\lib\site-packages\flask_login\utils.py", line 26, in <lambda>
    current_user = LocalProxy(lambda: _get_user())
  File "C:\microblog\venv\lib\site-packages\flask_login\utils.py", line 346, in _get_user
    current_app.login_manager._load_user()
  File "C:\microblog\venv\lib\site-packages\flask_login\login_manager.py", line 318, in _load_user
    user = self._user_callback(user_id)
  File "C:\microblog\app\models.py", line 126, in load_user
    return User.query.get(int(id))
  File "<string>", line 2, in get
  File "C:\microblog\venv\lib\site-packages\sqlalchemy\util\deprecations.py", line 401, in warned
    return fn(*args, **kwargs)
  File "C:\microblog\venv\lib\site-packages\sqlalchemy\orm\query.py", line 943, in get
    return self._get_impl(ident, loading.load_on_pk_identity)
  File "C:\microblog\venv\lib\site-packages\sqlalchemy\orm\query.py", line 947, in _get_impl
    return self.session._get_impl(
  File "C:\microblog\venv\lib\site-packages\sqlalchemy\orm\session.py", line 2892, in _get_impl
    return db_load_fn(
  File "C:\microblog\venv\lib\site-packages\sqlalchemy\orm\loading.py", line 530, in load_on_pk_identity
    session.execute(
  File "C:\microblog\venv\lib\site-packages\sqlalchemy\orm\session.py", line 1692, in execute
    result = conn._execute_20(statement, params or {}, execution_options)
  File "C:\microblog\venv\lib\site-packages\sqlalchemy\engine\base.py", line 1614, in _execute_20
    return meth(self, args_10style, kwargs_10style, execution_options)
  File "C:\microblog\venv\lib\site-packages\sqlalchemy\sql\elements.py", line 325, in _execute_on_connection
    return connection._execute_clauseelement(
  File "C:\microblog\venv\lib\site-packages\sqlalchemy\engine\base.py", line 1481, in _execute_clauseelement
    ret = self._execute_context(
  File "C:\microblog\venv\lib\site-packages\sqlalchemy\engine\base.py", line 1845, in _execute_context
    self._handle_dbapi_exception(
  File "C:\microblog\venv\lib\site-packages\sqlalchemy\engine\base.py", line 2026, in _handle_dbapi_exception
    util.raise_(
  File "C:\microblog\venv\lib\site-packages\sqlalchemy\util\compat.py", line 207, in raise_
    raise exception
  File "C:\microblog\venv\lib\site-packages\sqlalchemy\engine\base.py", line 1802, in _execute_context
    self.dialect.do_execute(
  File "C:\microblog\venv\lib\site-packages\sqlalchemy\engine\default.py", line 732, in do_execute
    cursor.execute(statement, parameters)
sqlalchemy.exc.OperationalError: (sqlite3.OperationalError) no such table: user
[SQL: SELECT user.id AS user_id, user.username AS user_username, user.email AS user_email, user.password_hash AS user_password_hash, user.about_me AS user_about_me, user.last_seen AS user_last_seen 
FROM user 
WHERE user.id = ?]
[parameters: (8,)]
(Background on this error at: https://sqlalche.me/e/14/e3q8)
